{
 "cells": [
  {
   "cell_type": "code",
   "execution_count": 21,
   "metadata": {},
   "outputs": [],
   "source": [
    "from tensorflow import keras\n",
    "from tensorflow.keras.datasets import imdb\n",
    "from sklearn.model_selection import train_test_split\n",
    "import numpy as np\n",
    "import pandas as pd\n",
    "import matplotlib.pyplot as plt\n",
    "import matplotlib\n",
    "matplotlib.rcParams['axes.unicode_minus'] = False  # 마이너스 표시 해결\n",
    "# 한글설정\n",
    "matplotlib.rcParams['font.family'] = 'Malgun Gothic' # windows 사용자\n",
    "# matplotlib.rcParams['font.family'] = 'AppleGothic Gothic' # Mac사용자\n",
    "matplotlib.rcParams['font.size'] = '10' # 글자크기"
   ]
  },
  {
   "cell_type": "code",
   "execution_count": 22,
   "metadata": {},
   "outputs": [],
   "source": [
    "(train_input, train_target), (test_input, test_target) = keras.datasets.imdb.load_data(\n",
    "    num_words=1000\n",
    ")"
   ]
  },
  {
   "cell_type": "code",
   "execution_count": 23,
   "metadata": {},
   "outputs": [
    {
     "name": "stdout",
     "output_type": "stream",
     "text": [
      "(25000,) (25000,)\n"
     ]
    }
   ],
   "source": [
    "print(train_input.shape, test_input.shape)"
   ]
  },
  {
   "cell_type": "code",
   "execution_count": 24,
   "metadata": {},
   "outputs": [],
   "source": [
    "from sklearn.model_selection import train_test_split\n",
    "train_input, val_input, train_target, val_target = train_test_split(\n",
    "    train_input, train_target, test_size=0.2, random_state=42\n",
    ")"
   ]
  },
  {
   "cell_type": "code",
   "execution_count": 25,
   "metadata": {},
   "outputs": [
    {
     "data": {
      "text/plain": [
       "array([259, 520, 290, ..., 300,  70,  77])"
      ]
     },
     "execution_count": 25,
     "metadata": {},
     "output_type": "execute_result"
    }
   ],
   "source": [
    "lengths = np.array([ len(x) for x in train_input])\n",
    "lengths"
   ]
  },
  {
   "cell_type": "code",
   "execution_count": 26,
   "metadata": {},
   "outputs": [],
   "source": [
    "from tensorflow.keras.preprocessing.sequence import pad_sequences\n",
    "train_seq = pad_sequences(train_input, maxlen=100)\n"
   ]
  },
  {
   "cell_type": "code",
   "execution_count": 27,
   "metadata": {},
   "outputs": [],
   "source": [
    "# 검증세트\n",
    "val_seq = pad_sequences(val_input, maxlen=100)\n"
   ]
  },
  {
   "cell_type": "code",
   "execution_count": 28,
   "metadata": {},
   "outputs": [
    {
     "name": "stderr",
     "output_type": "stream",
     "text": [
      "c:\\Python312\\Lib\\site-packages\\keras\\src\\layers\\core\\embedding.py:90: UserWarning: Argument `input_length` is deprecated. Just remove it.\n",
      "  warnings.warn(\n"
     ]
    }
   ],
   "source": [
    "model = keras.Sequential()\n",
    "\n",
    "model.add(keras.layers.Embedding(500, 16, input_length=100))\n",
    "model.add(keras.layers.SimpleRNN(8))\n",
    "model.add(keras.layers.Dense(1,activation='sigmoid'))\n"
   ]
  },
  {
   "cell_type": "code",
   "execution_count": 29,
   "metadata": {},
   "outputs": [
    {
     "name": "stdout",
     "output_type": "stream",
     "text": [
      "Epoch 1/100\n"
     ]
    },
    {
     "ename": "InvalidArgumentError",
     "evalue": "Graph execution error:\n\nDetected at node sequential_3_1/embedding_3_1/GatherV2 defined at (most recent call last):\n  File \"<frozen runpy>\", line 198, in _run_module_as_main\n\n  File \"<frozen runpy>\", line 88, in _run_code\n\n  File \"C:\\Users\\KOREAVC\\AppData\\Roaming\\Python\\Python312\\site-packages\\ipykernel_launcher.py\", line 18, in <module>\n\n  File \"C:\\Users\\KOREAVC\\AppData\\Roaming\\Python\\Python312\\site-packages\\traitlets\\config\\application.py\", line 1075, in launch_instance\n\n  File \"C:\\Users\\KOREAVC\\AppData\\Roaming\\Python\\Python312\\site-packages\\ipykernel\\kernelapp.py\", line 739, in start\n\n  File \"C:\\Users\\KOREAVC\\AppData\\Roaming\\Python\\Python312\\site-packages\\tornado\\platform\\asyncio.py\", line 205, in start\n\n  File \"c:\\Python312\\Lib\\asyncio\\base_events.py\", line 641, in run_forever\n\n  File \"c:\\Python312\\Lib\\asyncio\\base_events.py\", line 1987, in _run_once\n\n  File \"c:\\Python312\\Lib\\asyncio\\events.py\", line 88, in _run\n\n  File \"C:\\Users\\KOREAVC\\AppData\\Roaming\\Python\\Python312\\site-packages\\ipykernel\\kernelbase.py\", line 545, in dispatch_queue\n\n  File \"C:\\Users\\KOREAVC\\AppData\\Roaming\\Python\\Python312\\site-packages\\ipykernel\\kernelbase.py\", line 534, in process_one\n\n  File \"C:\\Users\\KOREAVC\\AppData\\Roaming\\Python\\Python312\\site-packages\\ipykernel\\kernelbase.py\", line 437, in dispatch_shell\n\n  File \"C:\\Users\\KOREAVC\\AppData\\Roaming\\Python\\Python312\\site-packages\\ipykernel\\ipkernel.py\", line 362, in execute_request\n\n  File \"C:\\Users\\KOREAVC\\AppData\\Roaming\\Python\\Python312\\site-packages\\ipykernel\\kernelbase.py\", line 778, in execute_request\n\n  File \"C:\\Users\\KOREAVC\\AppData\\Roaming\\Python\\Python312\\site-packages\\ipykernel\\ipkernel.py\", line 449, in do_execute\n\n  File \"C:\\Users\\KOREAVC\\AppData\\Roaming\\Python\\Python312\\site-packages\\ipykernel\\zmqshell.py\", line 549, in run_cell\n\n  File \"C:\\Users\\KOREAVC\\AppData\\Roaming\\Python\\Python312\\site-packages\\IPython\\core\\interactiveshell.py\", line 3075, in run_cell\n\n  File \"C:\\Users\\KOREAVC\\AppData\\Roaming\\Python\\Python312\\site-packages\\IPython\\core\\interactiveshell.py\", line 3130, in _run_cell\n\n  File \"C:\\Users\\KOREAVC\\AppData\\Roaming\\Python\\Python312\\site-packages\\IPython\\core\\async_helpers.py\", line 129, in _pseudo_sync_runner\n\n  File \"C:\\Users\\KOREAVC\\AppData\\Roaming\\Python\\Python312\\site-packages\\IPython\\core\\interactiveshell.py\", line 3334, in run_cell_async\n\n  File \"C:\\Users\\KOREAVC\\AppData\\Roaming\\Python\\Python312\\site-packages\\IPython\\core\\interactiveshell.py\", line 3517, in run_ast_nodes\n\n  File \"C:\\Users\\KOREAVC\\AppData\\Roaming\\Python\\Python312\\site-packages\\IPython\\core\\interactiveshell.py\", line 3577, in run_code\n\n  File \"C:\\Users\\KOREAVC\\AppData\\Local\\Temp\\ipykernel_15072\\3434695653.py\", line 11, in <module>\n\n  File \"c:\\Python312\\Lib\\site-packages\\keras\\src\\utils\\traceback_utils.py\", line 117, in error_handler\n\n  File \"c:\\Python312\\Lib\\site-packages\\keras\\src\\backend\\tensorflow\\trainer.py\", line 314, in fit\n\n  File \"c:\\Python312\\Lib\\site-packages\\keras\\src\\backend\\tensorflow\\trainer.py\", line 117, in one_step_on_iterator\n\n  File \"c:\\Python312\\Lib\\site-packages\\keras\\src\\backend\\tensorflow\\trainer.py\", line 104, in one_step_on_data\n\n  File \"c:\\Python312\\Lib\\site-packages\\keras\\src\\backend\\tensorflow\\trainer.py\", line 51, in train_step\n\n  File \"c:\\Python312\\Lib\\site-packages\\keras\\src\\utils\\traceback_utils.py\", line 117, in error_handler\n\n  File \"c:\\Python312\\Lib\\site-packages\\keras\\src\\layers\\layer.py\", line 846, in __call__\n\n  File \"c:\\Python312\\Lib\\site-packages\\keras\\src\\utils\\traceback_utils.py\", line 117, in error_handler\n\n  File \"c:\\Python312\\Lib\\site-packages\\keras\\src\\ops\\operation.py\", line 48, in __call__\n\n  File \"c:\\Python312\\Lib\\site-packages\\keras\\src\\utils\\traceback_utils.py\", line 156, in error_handler\n\n  File \"c:\\Python312\\Lib\\site-packages\\keras\\src\\models\\sequential.py\", line 209, in call\n\n  File \"c:\\Python312\\Lib\\site-packages\\keras\\src\\models\\functional.py\", line 202, in call\n\n  File \"c:\\Python312\\Lib\\site-packages\\keras\\src\\ops\\function.py\", line 155, in _run_through_graph\n\n  File \"c:\\Python312\\Lib\\site-packages\\keras\\src\\models\\functional.py\", line 592, in call\n\n  File \"c:\\Python312\\Lib\\site-packages\\keras\\src\\utils\\traceback_utils.py\", line 117, in error_handler\n\n  File \"c:\\Python312\\Lib\\site-packages\\keras\\src\\layers\\layer.py\", line 846, in __call__\n\n  File \"c:\\Python312\\Lib\\site-packages\\keras\\src\\utils\\traceback_utils.py\", line 117, in error_handler\n\n  File \"c:\\Python312\\Lib\\site-packages\\keras\\src\\ops\\operation.py\", line 48, in __call__\n\n  File \"c:\\Python312\\Lib\\site-packages\\keras\\src\\utils\\traceback_utils.py\", line 156, in error_handler\n\n  File \"c:\\Python312\\Lib\\site-packages\\keras\\src\\layers\\core\\embedding.py\", line 146, in call\n\n  File \"c:\\Python312\\Lib\\site-packages\\keras\\src\\ops\\numpy.py\", line 4850, in take\n\n  File \"c:\\Python312\\Lib\\site-packages\\keras\\src\\backend\\tensorflow\\numpy.py\", line 1940, in take\n\nindices[21,35] = 518 is not in [0, 500)\n\t [[{{node sequential_3_1/embedding_3_1/GatherV2}}]] [Op:__inference_one_step_on_iterator_8438]",
     "output_type": "error",
     "traceback": [
      "\u001b[1;31m---------------------------------------------------------------------------\u001b[0m",
      "\u001b[1;31mInvalidArgumentError\u001b[0m                      Traceback (most recent call last)",
      "Cell \u001b[1;32mIn[29], line 11\u001b[0m\n\u001b[0;32m      9\u001b[0m early_stopping_cb \u001b[38;5;241m=\u001b[39m keras\u001b[38;5;241m.\u001b[39mcallbacks\u001b[38;5;241m.\u001b[39mEarlyStopping(patience\u001b[38;5;241m=\u001b[39m\u001b[38;5;241m3\u001b[39m,restore_best_weights\u001b[38;5;241m=\u001b[39m\u001b[38;5;28;01mTrue\u001b[39;00m )\n\u001b[0;32m     10\u001b[0m \u001b[38;5;66;03m# 모델훈련 : train_oh -> train_seq 사용\u001b[39;00m\n\u001b[1;32m---> 11\u001b[0m history \u001b[38;5;241m=\u001b[39m \u001b[43mmodel\u001b[49m\u001b[38;5;241;43m.\u001b[39;49m\u001b[43mfit\u001b[49m\u001b[43m(\u001b[49m\u001b[43mtrain_seq\u001b[49m\u001b[43m,\u001b[49m\u001b[43mtrain_target\u001b[49m\u001b[43m,\u001b[49m\u001b[43mbatch_size\u001b[49m\u001b[38;5;241;43m=\u001b[39;49m\u001b[38;5;241;43m64\u001b[39;49m\u001b[43m,\u001b[49m\u001b[43mepochs\u001b[49m\u001b[38;5;241;43m=\u001b[39;49m\u001b[38;5;241;43m100\u001b[39;49m\u001b[43m,\u001b[49m\n\u001b[0;32m     12\u001b[0m \u001b[43m                    \u001b[49m\u001b[43mvalidation_data\u001b[49m\u001b[38;5;241;43m=\u001b[39;49m\u001b[43m(\u001b[49m\u001b[43mval_seq\u001b[49m\u001b[43m,\u001b[49m\u001b[43mval_target\u001b[49m\u001b[43m)\u001b[49m\u001b[43m,\u001b[49m\u001b[43m \u001b[49m\u001b[43mcallbacks\u001b[49m\u001b[38;5;241;43m=\u001b[39;49m\u001b[43m[\u001b[49m\u001b[43mcheckpoint_cb\u001b[49m\u001b[43m,\u001b[49m\u001b[43mearly_stopping_cb\u001b[49m\u001b[43m]\u001b[49m\u001b[43m)\u001b[49m\n",
      "File \u001b[1;32mc:\\Python312\\Lib\\site-packages\\keras\\src\\utils\\traceback_utils.py:122\u001b[0m, in \u001b[0;36mfilter_traceback.<locals>.error_handler\u001b[1;34m(*args, **kwargs)\u001b[0m\n\u001b[0;32m    119\u001b[0m     filtered_tb \u001b[38;5;241m=\u001b[39m _process_traceback_frames(e\u001b[38;5;241m.\u001b[39m__traceback__)\n\u001b[0;32m    120\u001b[0m     \u001b[38;5;66;03m# To get the full stack trace, call:\u001b[39;00m\n\u001b[0;32m    121\u001b[0m     \u001b[38;5;66;03m# `keras.config.disable_traceback_filtering()`\u001b[39;00m\n\u001b[1;32m--> 122\u001b[0m     \u001b[38;5;28;01mraise\u001b[39;00m e\u001b[38;5;241m.\u001b[39mwith_traceback(filtered_tb) \u001b[38;5;28;01mfrom\u001b[39;00m \u001b[38;5;28;01mNone\u001b[39;00m\n\u001b[0;32m    123\u001b[0m \u001b[38;5;28;01mfinally\u001b[39;00m:\n\u001b[0;32m    124\u001b[0m     \u001b[38;5;28;01mdel\u001b[39;00m filtered_tb\n",
      "File \u001b[1;32mc:\\Python312\\Lib\\site-packages\\tensorflow\\python\\eager\\execute.py:53\u001b[0m, in \u001b[0;36mquick_execute\u001b[1;34m(op_name, num_outputs, inputs, attrs, ctx, name)\u001b[0m\n\u001b[0;32m     51\u001b[0m \u001b[38;5;28;01mtry\u001b[39;00m:\n\u001b[0;32m     52\u001b[0m   ctx\u001b[38;5;241m.\u001b[39mensure_initialized()\n\u001b[1;32m---> 53\u001b[0m   tensors \u001b[38;5;241m=\u001b[39m pywrap_tfe\u001b[38;5;241m.\u001b[39mTFE_Py_Execute(ctx\u001b[38;5;241m.\u001b[39m_handle, device_name, op_name,\n\u001b[0;32m     54\u001b[0m                                       inputs, attrs, num_outputs)\n\u001b[0;32m     55\u001b[0m \u001b[38;5;28;01mexcept\u001b[39;00m core\u001b[38;5;241m.\u001b[39m_NotOkStatusException \u001b[38;5;28;01mas\u001b[39;00m e:\n\u001b[0;32m     56\u001b[0m   \u001b[38;5;28;01mif\u001b[39;00m name \u001b[38;5;129;01mis\u001b[39;00m \u001b[38;5;129;01mnot\u001b[39;00m \u001b[38;5;28;01mNone\u001b[39;00m:\n",
      "\u001b[1;31mInvalidArgumentError\u001b[0m: Graph execution error:\n\nDetected at node sequential_3_1/embedding_3_1/GatherV2 defined at (most recent call last):\n  File \"<frozen runpy>\", line 198, in _run_module_as_main\n\n  File \"<frozen runpy>\", line 88, in _run_code\n\n  File \"C:\\Users\\KOREAVC\\AppData\\Roaming\\Python\\Python312\\site-packages\\ipykernel_launcher.py\", line 18, in <module>\n\n  File \"C:\\Users\\KOREAVC\\AppData\\Roaming\\Python\\Python312\\site-packages\\traitlets\\config\\application.py\", line 1075, in launch_instance\n\n  File \"C:\\Users\\KOREAVC\\AppData\\Roaming\\Python\\Python312\\site-packages\\ipykernel\\kernelapp.py\", line 739, in start\n\n  File \"C:\\Users\\KOREAVC\\AppData\\Roaming\\Python\\Python312\\site-packages\\tornado\\platform\\asyncio.py\", line 205, in start\n\n  File \"c:\\Python312\\Lib\\asyncio\\base_events.py\", line 641, in run_forever\n\n  File \"c:\\Python312\\Lib\\asyncio\\base_events.py\", line 1987, in _run_once\n\n  File \"c:\\Python312\\Lib\\asyncio\\events.py\", line 88, in _run\n\n  File \"C:\\Users\\KOREAVC\\AppData\\Roaming\\Python\\Python312\\site-packages\\ipykernel\\kernelbase.py\", line 545, in dispatch_queue\n\n  File \"C:\\Users\\KOREAVC\\AppData\\Roaming\\Python\\Python312\\site-packages\\ipykernel\\kernelbase.py\", line 534, in process_one\n\n  File \"C:\\Users\\KOREAVC\\AppData\\Roaming\\Python\\Python312\\site-packages\\ipykernel\\kernelbase.py\", line 437, in dispatch_shell\n\n  File \"C:\\Users\\KOREAVC\\AppData\\Roaming\\Python\\Python312\\site-packages\\ipykernel\\ipkernel.py\", line 362, in execute_request\n\n  File \"C:\\Users\\KOREAVC\\AppData\\Roaming\\Python\\Python312\\site-packages\\ipykernel\\kernelbase.py\", line 778, in execute_request\n\n  File \"C:\\Users\\KOREAVC\\AppData\\Roaming\\Python\\Python312\\site-packages\\ipykernel\\ipkernel.py\", line 449, in do_execute\n\n  File \"C:\\Users\\KOREAVC\\AppData\\Roaming\\Python\\Python312\\site-packages\\ipykernel\\zmqshell.py\", line 549, in run_cell\n\n  File \"C:\\Users\\KOREAVC\\AppData\\Roaming\\Python\\Python312\\site-packages\\IPython\\core\\interactiveshell.py\", line 3075, in run_cell\n\n  File \"C:\\Users\\KOREAVC\\AppData\\Roaming\\Python\\Python312\\site-packages\\IPython\\core\\interactiveshell.py\", line 3130, in _run_cell\n\n  File \"C:\\Users\\KOREAVC\\AppData\\Roaming\\Python\\Python312\\site-packages\\IPython\\core\\async_helpers.py\", line 129, in _pseudo_sync_runner\n\n  File \"C:\\Users\\KOREAVC\\AppData\\Roaming\\Python\\Python312\\site-packages\\IPython\\core\\interactiveshell.py\", line 3334, in run_cell_async\n\n  File \"C:\\Users\\KOREAVC\\AppData\\Roaming\\Python\\Python312\\site-packages\\IPython\\core\\interactiveshell.py\", line 3517, in run_ast_nodes\n\n  File \"C:\\Users\\KOREAVC\\AppData\\Roaming\\Python\\Python312\\site-packages\\IPython\\core\\interactiveshell.py\", line 3577, in run_code\n\n  File \"C:\\Users\\KOREAVC\\AppData\\Local\\Temp\\ipykernel_15072\\3434695653.py\", line 11, in <module>\n\n  File \"c:\\Python312\\Lib\\site-packages\\keras\\src\\utils\\traceback_utils.py\", line 117, in error_handler\n\n  File \"c:\\Python312\\Lib\\site-packages\\keras\\src\\backend\\tensorflow\\trainer.py\", line 314, in fit\n\n  File \"c:\\Python312\\Lib\\site-packages\\keras\\src\\backend\\tensorflow\\trainer.py\", line 117, in one_step_on_iterator\n\n  File \"c:\\Python312\\Lib\\site-packages\\keras\\src\\backend\\tensorflow\\trainer.py\", line 104, in one_step_on_data\n\n  File \"c:\\Python312\\Lib\\site-packages\\keras\\src\\backend\\tensorflow\\trainer.py\", line 51, in train_step\n\n  File \"c:\\Python312\\Lib\\site-packages\\keras\\src\\utils\\traceback_utils.py\", line 117, in error_handler\n\n  File \"c:\\Python312\\Lib\\site-packages\\keras\\src\\layers\\layer.py\", line 846, in __call__\n\n  File \"c:\\Python312\\Lib\\site-packages\\keras\\src\\utils\\traceback_utils.py\", line 117, in error_handler\n\n  File \"c:\\Python312\\Lib\\site-packages\\keras\\src\\ops\\operation.py\", line 48, in __call__\n\n  File \"c:\\Python312\\Lib\\site-packages\\keras\\src\\utils\\traceback_utils.py\", line 156, in error_handler\n\n  File \"c:\\Python312\\Lib\\site-packages\\keras\\src\\models\\sequential.py\", line 209, in call\n\n  File \"c:\\Python312\\Lib\\site-packages\\keras\\src\\models\\functional.py\", line 202, in call\n\n  File \"c:\\Python312\\Lib\\site-packages\\keras\\src\\ops\\function.py\", line 155, in _run_through_graph\n\n  File \"c:\\Python312\\Lib\\site-packages\\keras\\src\\models\\functional.py\", line 592, in call\n\n  File \"c:\\Python312\\Lib\\site-packages\\keras\\src\\utils\\traceback_utils.py\", line 117, in error_handler\n\n  File \"c:\\Python312\\Lib\\site-packages\\keras\\src\\layers\\layer.py\", line 846, in __call__\n\n  File \"c:\\Python312\\Lib\\site-packages\\keras\\src\\utils\\traceback_utils.py\", line 117, in error_handler\n\n  File \"c:\\Python312\\Lib\\site-packages\\keras\\src\\ops\\operation.py\", line 48, in __call__\n\n  File \"c:\\Python312\\Lib\\site-packages\\keras\\src\\utils\\traceback_utils.py\", line 156, in error_handler\n\n  File \"c:\\Python312\\Lib\\site-packages\\keras\\src\\layers\\core\\embedding.py\", line 146, in call\n\n  File \"c:\\Python312\\Lib\\site-packages\\keras\\src\\ops\\numpy.py\", line 4850, in take\n\n  File \"c:\\Python312\\Lib\\site-packages\\keras\\src\\backend\\tensorflow\\numpy.py\", line 1940, in take\n\nindices[21,35] = 518 is not in [0, 500)\n\t [[{{node sequential_3_1/embedding_3_1/GatherV2}}]] [Op:__inference_one_step_on_iterator_8438]"
     ]
    }
   ],
   "source": [
    "# 인공신경망 훈련 동일\n",
    "# Flatten 필요 없음. \n",
    "# 원핫인코딩을 사용하지 않음. -- > 임베딩 사용 ==> train_oh -> train_seq 사용\n",
    "rmsprop = keras.optimizers.RMSprop(learning_rate=0.0001)\n",
    "model.compile(optimizer=rmsprop, loss='binary_crossentropy',metrics=['accuracy'])\n",
    "# 콜백모델체크포인트 \n",
    "checkpoint_cb = keras.callbacks.ModelCheckpoint('simpleRnn_embedding_model.keras')\n",
    "# 종기종료 \n",
    "early_stopping_cb = keras.callbacks.EarlyStopping(patience=3,restore_best_weights=True )\n",
    "# 모델훈련 : train_oh -> train_seq 사용\n",
    "history = model.fit(train_seq,train_target,batch_size=64,epochs=100,\n",
    "                    validation_data=(val_seq,val_target), callbacks=[checkpoint_cb,early_stopping_cb])\n"
   ]
  },
  {
   "cell_type": "code",
   "execution_count": null,
   "metadata": {},
   "outputs": [],
   "source": [
    "# 시퀀스패딩\n",
    "test_seq = pad_sequences(test_input, maxlen=100)\n",
    "# 원핫인코딩\n",
    "model.evaluate(test_seq, test_target)\n"
   ]
  }
 ],
 "metadata": {
  "kernelspec": {
   "display_name": "Python 3",
   "language": "python",
   "name": "python3"
  },
  "language_info": {
   "codemirror_mode": {
    "name": "ipython",
    "version": 3
   },
   "file_extension": ".py",
   "mimetype": "text/x-python",
   "name": "python",
   "nbconvert_exporter": "python",
   "pygments_lexer": "ipython3",
   "version": "3.12.3"
  }
 },
 "nbformat": 4,
 "nbformat_minor": 2
}
